<?xml version="1.0"?>
<robot name="waymasterv1">

    
    <material name="white">
        <color rgba="1.0 1.0 1.0 1.0"/>
    </material>

    <material name="orange">
        <color rgba="1.0 0.3 0.1 1.0"/>
    </material>

    <material name="blue">
        <color rgba="0.2 0.2 1.0 1.0"/>
    </material>

    <material name="black">
        <color rgba="0 0 0 1.0"/>
    </material>

    <material name="red">
        <color rgba="1 0 0 1.0"/>
    </material>

    <!-- BASE LINK -->
    <link name="base_link"></link>

    <!-- BASE FOOTPRINT LINK -->
    <joint name="base_footprint_joint" type="fixed">
        <origin xyz="0.0 0.0 0.0" rpy="0.0 0.0 0.0"/>
        <parent link="base_link"/>
        <child link="base_footprint"/>
    </joint>

    <link name="base_footprint"></link>

    <!-- CHASSIS LINK -->
    <joint name="chassis_joint" type="fixed">
        <parent link="base_link"/>
        <child link="chassis"/>
        <origin xyz="-0.1 0.0 0.0" rpy="0.0 0.0 0.0"/>
    </joint>

    <link name="chassis">
        <visual>
            <origin xyz="0.15 0.0 0.145"/>
            <geometry>
                <box size="0.3 0.23 0.15"/>
            </geometry>
            <material name="blue">
            </material>
        </visual>
        <collision>
            <origin xyz="0.15 0.0 0.145"/>
            <geometry>
                <box size="0.3 0.23 0.15"/>
            </geometry>
        </collision>

        <inertial>
            <origin xyz="0.15 0.0 0.145" rpy="0.0 0.0 0.0"/>
            <mass value="0.5" />
            <inertia ixx="0.003141" ixy="0.0" ixz="0.0"
                    iyy="0.003141" iyz="0.0"
                    izz="0.003141" />
        </inertial>
    </link>
    <gazebo reference="chassis">
        <material>Gazebo/Blue</material>
    </gazebo>




    <!-- LEFT WHEEL -->

    <joint name="left_wheel_joint" type="continuous">
        <parent link="base_link"/>
        <child link="left_wheel"/>
        <origin xyz="0.0 0.14 0.0515" rpy="-1.571 0.0 0.0"/>
        <axis xyz="0.0 0.0 1.0"/>
    </joint>

    <link name="left_wheel">
        <visual>
            <geometry> 
                <cylinder radius="0.05" length="0.04"/>
            </geometry>
            <material name="orange"/>
        </visual>
        <collision>
            <geometry>
                <cylinder radius="0.05" length="0.04"/>
            </geometry>
        </collision>
        <inertial>
            <origin xyz="0.0 0.0 0.0" rpy="0.0 0.0 0.0"/>
            <mass value="0.1" />
            <inertia ixx="0.0000758" ixy="0.0" ixz="0.0"
                    iyy="0.0000758" iyz="0.0"
                    izz="0.000125" />
        </inertial>
    </link>

    <gazebo reference="left_wheel">
        <material>Gazebo/Orange</material>
    </gazebo>

    <!-- RIGHT WHEEL -->

    <joint name="right_wheel_joint" type="continuous">
        <parent link="base_link"/>
        <child link="right_wheel"/>
        <origin xyz="0.0 -0.14 0.0515" rpy="1.571 0.0 0.0"/>
        <axis xyz="0.0 0.0 -1.0"/>
    </joint>

    <link name="right_wheel">
        <visual>
            <geometry>
                <cylinder radius="0.05" length="0.04"/>
            </geometry>
            <material name="orange"/>
        </visual>
        <collision>
            <geometry>
                <cylinder radius="0.05" length="0.04"/>
            </geometry>
        </collision>
        <inertial>
            <origin xyz="0.0 0.0 0.0" rpy="0.0 0.0 0.0"/>
            <mass value="0.1" />
            <inertia ixx="0.0000758" ixy="0.0" ixz="0.0"
                    iyy="0.0000758" iyz="0.0"
                    izz="0.0000125" />
        </inertial>
    </link>

    <gazebo reference="right_wheel">
        <material>Gazebo/Orange</material>
    </gazebo>

    <!-- CASTOR WHEEL LINK -->

    <joint name="castor_wheel_joint" type="fixed">
        <parent link="chassis"/>
        <child link="castor_wheel"/>
        <origin xyz="0.24 0.0 0.0515" rpy="0.0 0.0 0.0"/>
    </joint>

    <link name="castor_wheel">
        <visual>
            <geometry>
                <sphere radius="0.05"/>
            </geometry>
            <material name="black"/>
        </visual>
        <collision>
            <geometry>
                <sphere radius="0.05"/>
            </geometry>
        </collision>
        <inertial>
            <origin xyz="0.0 0.0 0.0" rpy="0.0 0.0 0.0"/>
            <mass value="0.1" />
            <inertia ixx="0.0001" ixy="0.0" ixz="0.0"
                    iyy="0.0001" iyz="0.0"
                    izz="0.0001" />
        </inertial>

        <inertial>
            <origin xyz="0.0 0.0 0.0" rpy="0.0 0.0 0.0"/>
            <mass value="0.0"/>
            <inertia ixx="0.0" ixy="0.0" ixz="0.0" iyy="0.0" iyz="0.0" izz="0.0"/>
        </inertial>
        
    </link>

    <gazebo reference="castor_wheel">
        <material>Gazebo/Black</material>
        <mu1 value="0.001"/>
        <mu2 value="0.001"/>
    </gazebo>

    <gazebo>
        <plugin name="differential_drive_controller" filename="libgazebo_ros_diff_drive.so">
            <alwaysOn>true</alwaysOn>
            <legacyMode>false</legacyMode>
            <updateRate>40</updateRate>
            <leftJoint>left_wheel_joint</leftJoint>
            <rightJoint>right_wheel_joint</rightJoint>
            <wheelSeparation>0.028</wheelSeparation>
            <wheelDiameter>0.067</wheelDiameter>
            <torque>2</torque>
            <commandTopic>cmd_vel</commandTopic>
            <odometryTopic>odom</odometryTopic>
            <odometryFrame>odom</odometryFrame>
            <robotBaseFrame>base_link</robotBaseFrame>
            <broadcastTF>true</broadcastTF>
        </plugin>
    </gazebo>

    <joint name="camera_joint" type="fixed">
        <parent link="chassis"/>
        <child link="camera_link"/>
        <origin xyz="0.122 0 0.212" rpy="0 0 0"/>
    </joint>

    <link name="camera_link">
        <visual>
            <geometry>
                <cylinder radius="0.05" length="0.04"/>
            </geometry>
            <material name="red"/>
        </visual>
        <visual>
            <origin xyz="0 0 -0.05"/>
            <geometry>
                <cylinder radius="0.01" length="0.1"/>
            </geometry>
            <material name="red"/>
        </visual>
        <collision>
            <geometry>
                <cylinder radius="0.05" length="0.04"/>
            </geometry>
        </collision>
        <inertial>
            <origin xyz="0.0 0.0 0.0" rpy="0.0 0.0 0.0"/>
            <mass value="0.1" />
            <inertia ixx="0.0000758" ixy="0.0" ixz="0.0"
                    iyy="0.0000758" iyz="0.0"
                    izz="0.0000125" />
        </inertial>
    </link>



</robot>
